<?xml version="1.0" encoding="UTF-8"?>
<testng-results skipped="0" failed="1" total="4" passed="3">
  <reporter-output>
  </reporter-output>
  <suite name="Default suite" duration-ms="47" started-at="2019-11-14T02:33:16Z" finished-at="2019-11-14T02:33:16Z">
    <groups>
    </groups>
    <test name="Default test" duration-ms="47" started-at="2019-11-14T02:33:16Z" finished-at="2019-11-14T02:33:16Z">
      <class name="task1.TestIWebShop">
        <test-method status="PASS" signature="send1()[pri:0, instance:task1.TestIWebShop@725bef66]" name="send1" duration-ms="16" started-at="2019-11-14T10:33:16Z" finished-at="2019-11-14T10:33:16Z">
          <reporter-output>
          </reporter-output>
        </test-method> <!-- send1 -->
        <test-method status="PASS" signature="send3()[pri:0, instance:task1.TestIWebShop@725bef66]" name="send3" duration-ms="15" started-at="2019-11-14T10:33:16Z" finished-at="2019-11-14T10:33:16Z">
          <reporter-output>
          </reporter-output>
        </test-method> <!-- send3 -->
        <test-method status="FAIL" signature="send2()[pri:0, instance:task1.TestIWebShop@725bef66]" name="send2" duration-ms="0" started-at="2019-11-14T10:33:16Z" finished-at="2019-11-14T10:33:16Z">
          <exception class="java.lang.AssertionError">
            <message>
              <![CDATA[expected [1] but found [9]]]>
            </message>
            <full-stacktrace>
              <![CDATA[java.lang.AssertionError: expected [1] but found [9]
	at org.testng.Assert.fail(Assert.java:94)
	at org.testng.Assert.failNotEquals(Assert.java:513)
	at org.testng.Assert.assertEqualsImpl(Assert.java:135)
	at org.testng.Assert.assertEquals(Assert.java:116)
	at org.testng.Assert.assertEquals(Assert.java:389)
	at org.testng.Assert.assertEquals(Assert.java:399)
	at task1.TestIWebShop.send2(TestIWebShop.java:17)
	at sun.reflect.NativeMethodAccessorImpl.invoke0(Native Method)
	at sun.reflect.NativeMethodAccessorImpl.invoke(NativeMethodAccessorImpl.java:62)
	at sun.reflect.DelegatingMethodAccessorImpl.invoke(DelegatingMethodAccessorImpl.java:43)
	at java.lang.reflect.Method.invoke(Method.java:497)
	at org.testng.internal.MethodInvocationHelper.invokeMethod(MethodInvocationHelper.java:86)
	at org.testng.internal.Invoker.invokeMethod(Invoker.java:645)
	at org.testng.internal.Invoker.invokeTestMethod(Invoker.java:822)
	at org.testng.internal.Invoker.invokeTestMethods(Invoker.java:1130)
	at org.testng.internal.TestMethodWorker.invokeTestMethods(TestMethodWorker.java:129)
	at org.testng.internal.TestMethodWorker.run(TestMethodWorker.java:112)
	at org.testng.TestRunner.privateRun(TestRunner.java:782)
	at org.testng.TestRunner.run(TestRunner.java:632)
	at org.testng.SuiteRunner.runTest(SuiteRunner.java:366)
	at org.testng.SuiteRunner.runSequentially(SuiteRunner.java:361)
	at org.testng.SuiteRunner.privateRun(SuiteRunner.java:319)
	at org.testng.SuiteRunner.run(SuiteRunner.java:268)
	at org.testng.SuiteRunnerWorker.runSuite(SuiteRunnerWorker.java:52)
	at org.testng.SuiteRunnerWorker.run(SuiteRunnerWorker.java:86)
	at org.testng.TestNG.runSuitesSequentially(TestNG.java:1244)
	at org.testng.TestNG.runSuitesLocally(TestNG.java:1169)
	at org.testng.TestNG.run(TestNG.java:1064)
	at org.testng.remote.RemoteTestNG.run(RemoteTestNG.java:113)
	at org.testng.remote.RemoteTestNG.initAndRun(RemoteTestNG.java:206)
	at org.testng.remote.RemoteTestNG.main(RemoteTestNG.java:177)
]]>
            </full-stacktrace>
          </exception> <!-- java.lang.AssertionError -->
          <reporter-output>
          </reporter-output>
        </test-method> <!-- send2 -->
        <test-method status="PASS" signature="send4()[pri:0, instance:task1.TestIWebShop@725bef66]" name="send4" duration-ms="0" started-at="2019-11-14T10:33:16Z" finished-at="2019-11-14T10:33:16Z">
          <reporter-output>
          </reporter-output>
        </test-method> <!-- send4 -->
      </class> <!-- task1.TestIWebShop -->
    </test> <!-- Default test -->
  </suite> <!-- Default suite -->
</testng-results>
